<?xml version="1.0" ?>
<!-- =================================================================================== -->
<!-- |    This document was autogenerated by xacro from urdf/camera.urdf.xacro         | -->
<!-- |    EDITING THIS FILE BY HAND IS NOT RECOMMENDED                                 | -->
<!-- =================================================================================== -->
<robot name="rover">
  <material name="grey">
    <color rgba="0.4 0.4 0.45 1"/>
  </material>
  <material name="pink">
    <color rgba="0.60 0.27 0.3 1"/>
  </material>
  <material name="light_green">
    <color rgba="0.3 0.6 0.3 1"/>
  </material>
  <link name="base_link">
    <visual>
      <geometry>
        <mesh filename="package://rover_sim/meshes/base_link.dae"/>
      </geometry>
    </visual>
    <collision>
      <geometry>
        <mesh filename="package://rover_sim/meshes/base_link.dae"/>
      </geometry>
      <surface>
        <friction>
          <ode>
            <mu>1.0</mu>
            <!-- longitudinal friction -->
            <mu2>1.0</mu2>
            <!-- lateral friction -->
            <slip1>0.0</slip1>
            <!-- slip in longitudinal direction -->
            <slip2>0.0</slip2>
            <!-- slip in lateral direction -->
          </ode>
        </friction>
        <contact>
          <ode>
            <kp>1e6</kp>
            <!-- contact stiffness -->
            <kd>1</kd>
            <!-- contact damping -->
          </ode>
        </contact>
      </surface>
    </collision>
    <inertial>
      <origin rpy="0 0 0" xyz="-0.20184 -0.000146 0.032825"/>
      <mass value="28.648383719388"/>
      <inertia ixx="0.044964" ixy="0.0" ixz="0.0" iyy="0.239861" iyz="0.0" izz="0.251238"/>
    </inertial>
  </link>
  <link name="left_front">
    <visual>
      <geometry>
        <mesh filename="package://rover_sim/meshes/left_front.dae"/>
      </geometry>
      <material name="pink"/>
    </visual>
    <collision>
      <geometry>
        <mesh filename="package://rover_sim/meshes/left_front.dae"/>
      </geometry>
      <surface>
        <friction>
          <ode>
            <mu>1.0</mu>
            <!-- longitudinal friction -->
            <mu2>1.0</mu2>
            <!-- lateral friction -->
            <slip1>0.0</slip1>
            <!-- slip in longitudinal direction -->
            <slip2>0.0</slip2>
            <!-- slip in lateral direction -->
          </ode>
        </friction>
        <contact>
          <ode>
            <kp>1e6</kp>
            <!-- contact stiffness -->
            <kd>1</kd>
            <!-- contact damping -->
          </ode>
        </contact>
      </surface>
    </collision>
    <inertial>
      <origin rpy="0 0 0" xyz="0.000053 0.04643 -0.000245"/>
      <mass value="3.6"/>
      <inertia ixx="0.017" ixy="0.0" ixz="0.0" iyy="0.028" iyz="0.0" izz="0.017"/>
    </inertial>
  </link>
  <joint name="left_front_joint" type="continuous">
    <parent link="base_link"/>
    <child link="left_front"/>
    <origin rpy="0 0 0" xyz="0.38106 0.31837 -0.16074"/>
    <axis xyz="0 1 0"/>
  </joint>
  <link name="right_front">
    <visual>
      <geometry>
        <mesh filename="package://rover_sim/meshes/right_front.dae"/>
      </geometry>
      <material name="pink"/>
    </visual>
    <collision>
      <geometry>
        <mesh filename="package://rover_sim/meshes/right_front.dae"/>
      </geometry>
      <surface>
        <friction>
          <ode>
            <mu>1.0</mu>
            <!-- longitudinal friction -->
            <mu2>1.0</mu2>
            <!-- lateral friction -->
            <slip1>0.0</slip1>
            <!-- slip in longitudinal direction -->
            <slip2>0.0</slip2>
            <!-- slip in lateral direction -->
          </ode>
        </friction>
        <contact>
          <ode>
            <kp>1e6</kp>
            <!-- contact stiffness -->
            <kd>1</kd>
            <!-- contact damping -->
          </ode>
        </contact>
      </surface>
    </collision>
    <inertial>
      <origin rpy="0 0 0" xyz="-0.000053 -0.04643 -0.000245"/>
      <mass value="3.6"/>
      <inertia ixx="0.017" ixy="0.0" ixz="0.0" iyy="0.028" iyz="0.0" izz="0.016"/>
    </inertial>
  </link>
  <joint name="right_front_joint" type="continuous">
    <parent link="base_link"/>
    <child link="right_front"/>
    <origin rpy="0 0 0" xyz="0.38106 -0.31837 -0.16074"/>
    <axis xyz="0 1 0"/>
  </joint>
  <link name="left_back">
    <visual>
      <geometry>
        <mesh filename="package://rover_sim/meshes/left_back.dae"/>
      </geometry>
      <material name="pink"/>
    </visual>
    <collision>
      <geometry>
        <mesh filename="package://rover_sim/meshes/left_back.dae"/>
      </geometry>
      <surface>
        <friction>
          <ode>
            <mu>1.0</mu>
            <!-- longitudinal friction -->
            <mu2>1.0</mu2>
            <!-- lateral friction -->
            <slip1>0.0</slip1>
            <!-- slip in longitudinal direction -->
            <slip2>0.0</slip2>
            <!-- slip in lateral direction -->
          </ode>
        </friction>
        <contact>
          <ode>
            <kp>1e6</kp>
            <!-- contact stiffness -->
            <kd>1</kd>
            <!-- contact damping -->
          </ode>
        </contact>
      </surface>
    </collision>
    <inertial>
      <origin rpy="0 0 0" xyz="0.000053 0.04643 -0.000245"/>
      <mass value="3.6"/>
      <inertia ixx="0.017" ixy="0.0" ixz="0.0" iyy="0.028" iyz="0.0" izz="0.017"/>
    </inertial>
  </link>
  <joint name="left_back_joint" type="continuous">
    <parent link="base_link"/>
    <child link="left_back"/>
    <origin rpy="0 0 0" xyz="-0.38139 0.31387 -0.16074"/>
    <axis xyz="0 1 0"/>
  </joint>
  <link name="right_back">
    <visual>
      <geometry>
        <mesh filename="package://rover_sim/meshes/right_back.dae"/>
      </geometry>
      <material name="pink"/>
    </visual>
    <collision>
      <geometry>
        <mesh filename="package://rover_sim/meshes/right_back.dae"/>
      </geometry>
      <surface>
        <friction>
          <ode>
            <mu>1.0</mu>
            <!-- longitudinal friction -->
            <mu2>1.0</mu2>
            <!-- lateral friction -->
            <slip1>0.0</slip1>
            <!-- slip in longitudinal direction -->
            <slip2>0.0</slip2>
            <!-- slip in lateral direction -->
          </ode>
        </friction>
        <contact>
          <ode>
            <kp>1e6</kp>
            <!-- contact stiffness -->
            <kd>1</kd>
            <!-- contact damping -->
          </ode>
        </contact>
      </surface>
    </collision>
    <inertial>
      <origin rpy="0 0 0" xyz="-0.000053 -0.04643 -0.000245"/>
      <mass value="3.6"/>
      <inertia ixx="0.017" ixy="0.0" ixz="0.0" iyy="0.028" iyz="0.0" izz="0.017"/>
    </inertial>
  </link>
  <joint name="right_back_joint" type="continuous">
    <parent link="base_link"/>
    <child link="right_back"/>
    <origin rpy="0 0 0" xyz="-0.38139 -0.31387 -0.16074"/>
    <axis xyz="0 1 0"/>
  </joint>
  <link name="lidar_link">
    <visual>
      <origin rpy="0 0 0" xyz="0 0 0"/>
      <geometry>
        <mesh filename="package://rover_sim/meshes/lidar.dae"/>
      </geometry>
      <material name="pink"/>
    </visual>
  </link>
  <joint name="lidar_joint" type="fixed">
    <parent link="base_link"/>
    <child link="lidar_link"/>
    <origin rpy="0 0 0" xyz="0.2 0 0.20682"/>
  </joint>
  <link name="imu_link">
    <visual>
      <origin rpy="0 0 0" xyz="0 0 0"/>
      <geometry>
        <box size="0.03 0.02 0.01"/>
      </geometry>
      <material name="grey"/>
    </visual>
  </link>
  <joint name="imu_joint" type="fixed">
    <parent link="base_link"/>
    <child link="imu_link"/>
    <origin rpy="0 0 0" xyz="0 0.05 0.031"/>
  </joint>
  <link name="gps_link">
    <visual>
      <origin rpy="0 0 0" xyz="0 0 0"/>
      <geometry>
        <box size="0.03 0.02 0.01"/>
      </geometry>
      <material name="light_green"/>
    </visual>
  </link>
  <joint name="gps_joint" type="fixed">
    <parent link="base_link"/>
    <child link="gps_link"/>
    <origin rpy="0 0 0" xyz="0 -0.05 0.031"/>
  </joint>
  <link name="camera_link">
    <visual>
      <geometry>
        <box size="0.03 0.09 0.03"/>
      </geometry>
      <material name="camera_material">
        <color rgba="0.3 0.3 0.3 1.0"/>
      </material>
    </visual>
    <inertial>
      <mass value="0.1"/>
      <origin rpy="0 0 0" xyz="0 0 0"/>
      <inertia ixx="1e-6" ixy="0" ixz="0" iyy="1e-6" iyz="0" izz="1e-6"/>
    </inertial>
  </link>
  <joint name="camera_joint" type="fixed">
    <parent link="base_link"/>
    <child link="camera_link"/>
    <origin rpy="0 0 0" xyz="0.28 0 0.12"/>
  </joint>
  <link name="camera_frame_link"/>
  <joint name="camera_link_joint" type="fixed">
    <parent link="camera_link"/>
    <child link="camera_frame_link"/>
    <origin rpy="-1.5707963267948966 0 -1.5707963267948966" xyz="0 0 0"/>
  </joint>
  <gazebo reference="camera_link">
    <sensor name="camera" type="depth">
      <update_rate>5</update_rate>
      <visualize>true</visualize>
      <camera>
        <horizontal_fov>1.5708</horizontal_fov>
        <image>
          <format>R8G8B8</format>
          <width>640</width>
          <height>480</height>
        </image>
        <clip>
          <near>.05</near>
          <far>20.0</far>
        </clip>
      </camera>
      <plugin filename="libgazebo_ros_camera.so" name="depth_camera">
        <ros>
          <namespace>/rover</namespace>
        </ros>
        <frame_name>camera_frame_link</frame_name>
      </plugin>
    </sensor>
  </gazebo>
  <gazebo reference="base_link">
    <sensor name="gps" type="gps">
      <always_on>true</always_on>
      <update_rate>10</update_rate>
      <visualize>true</visualize>
      <gps>
        <position_sensing>
          <horizontal>
            <noise type="gaussian">
              <mean>0.0</mean>
              <stddev>0.0002</stddev>
              <!-- ~20 cm noise -->
            </noise>
          </horizontal>
          <vertical>
            <noise type="gaussian">
              <mean>0.0</mean>
              <stddev>0.0004</stddev>
            </noise>
          </vertical>
        </position_sensing>
      </gps>
      <plugin filename="libgazebo_ros_gps_sensor.so" name="gps">
        <ros>
          <namespace>/rover</namespace>
          <remapping>fix:=gps/fix</remapping>
        </ros>
        <frame_id>gps_link</frame_id>
      </plugin>
    </sensor>
  </gazebo>
  <gazebo reference="imu_link">
    <sensor name="imu_sensor" type="imu">
      <always_on>true</always_on>
      <update_rate>100</update_rate>
      <visualize>true</visualize>
      <imu>
        <angular_velocity>
          <x>
            <noise type="gaussian">
              <mean>0.0</mean>
              <stddev>2e-4</stddev>
            </noise>
          </x>
          <y>
            <noise type="gaussian">
              <mean>0.0</mean>
              <stddev>2e-4</stddev>
            </noise>
          </y>
          <z>
            <noise type="gaussian">
              <mean>0.0</mean>
              <stddev>2e-4</stddev>
            </noise>
          </z>
        </angular_velocity>
        <linear_acceleration>
          <x>
            <noise type="gaussian">
              <mean>0.0</mean>
              <stddev>1.7e-2</stddev>
            </noise>
          </x>
          <y>
            <noise type="gaussian">
              <mean>0.0</mean>
              <stddev>1.7e-2</stddev>
            </noise>
          </y>
          <z>
            <noise type="gaussian">
              <mean>0.0</mean>
              <stddev>1.7e-2</stddev>
            </noise>
          </z>
        </linear_acceleration>
      </imu>
      <plugin filename="libgazebo_ros_imu_sensor.so" name="imu">
        <ros>
          <namespace>/rover</namespace>
          <remapping>~/out:=imu</remapping>
        </ros>
        <update_rate>100</update_rate>
        <!-- <gaussian_noise>0.0001</gaussian_noise> -->
        <!-- remove other noises before uncommenting it> -->
        <frame_name>imu_link</frame_name>
      </plugin>
    </sensor>
  </gazebo>
  <gazebo reference="lidar_link">
    <sensor name="laser" type="ray">
      <pose>0 0 0 0 0 0</pose>
      <visualize>true</visualize>
      <update_rate>10</update_rate>
      <ray>
        <scan>
          <horizontal>
            <samples>1024</samples>
            <resolution>1</resolution>
            <min_angle>-3.141593</min_angle>
            <max_angle>3.141593</max_angle>
          </horizontal>
        </scan>
        <range>
          <min>0.1</min>
          <max>15</max>
          <resolution>0.1</resolution>
        </range>
      </ray>
      <plugin filename="libgazebo_ros_ray_sensor.so" name="laser">
        <ros>
          <namespace>/rover</namespace>
          <remapping>~/out:=scan</remapping>
        </ros>
        <output_type>sensor_msgs/LaserScan</output_type>
        <frame_name>lidar_link</frame_name>
      </plugin>
    </sensor>
  </gazebo>
  <gazebo>
    <plugin filename="libgazebo_ros_joint_state_publisher.so" name="joint_state_publisher">
      <ros>
        <namespace>/rover</namespace>
      </ros>
      <update_rate>50</update_rate>
      <joint_name>left_front_joint</joint_name>
      <joint_name>left_back_joint</joint_name>
      <joint_name>right_front_joint</joint_name>
      <joint_name>right_back_joint</joint_name>
    </plugin>
  </gazebo>
  <gazebo>
    <plugin filename="libgazebo_ros_diff_drive.so" name="skid_steer_drive">
      <ros>
        <namespace>/rover</namespace>
      </ros>
      <num_wheel_pairs>2</num_wheel_pairs>
      <update_rate>30</update_rate>
      <!-- wheels -->
      <left_joint>left_front_joint</left_joint>
      <right_joint>right_front_joint</right_joint>
      <left_joint>left_back_joint</left_joint>
      <right_joint>right_back_joint</right_joint>
      <!-- kinematics -->
      <wheel_separation>0.76</wheel_separation>
      <wheel_separation>0.76</wheel_separation>
      <wheel_diameter>0.11</wheel_diameter>
      <wheel_diameter>0.11</wheel_diameter>
      <!-- limits -->
      <max_wheel_torque>20</max_wheel_torque>
      <max_wheel_acceleration>1.0</max_wheel_acceleration>
      <!-- output -->
      <publish_odom>true</publish_odom>
      <publish_odom_tf>true</publish_odom_tf>
      <publish_wheel_tf>true</publish_wheel_tf>
      <odometry_frame>odom</odometry_frame>
      <robot_base_frame>base_link</robot_base_frame>
    </plugin>
  </gazebo>
</robot>
